Workbook
Name BS_Check: Model!$F$108
Name currency: Inp!$F$26
Name L_Scenarios: Scenarios!$D$12:$D$14
Name LiveScenario: Scenarios!$D$11
Name million: Inp!$F$12
Name S_Circularity: Cover!$D$15
Name S_Scenarios: Scenarios!$E$12
Name thousand: Inp!$F$13

Sheet Cover
C7: =Hist!B1 -> FED Manufacturing
C8: ="Financial Model for "&Hist!I6+1&" to "&Hist!I6+5 -> Financial Model for 2025 to 2029
C11: Modeler: | D11: Animashaun Jafar
C12: Version: | D12: Ver 1.01
C13: Circularity in model | D13: ="Currently "&S_Circularity&" in the Net Interest Expense Line of the P&L" -> Currently OFF in the Net Interest Expense Line of the P&L
C14: Model Base Year | D14: =Hist!I6 -> 2024
C15: Circularity Toggle >>> | D15: OFF

Sheet Hist
B1: FED Manufacturing
B2: Income Statement
B4: ($ Millions)
G6: 2022 | H6: 2023 | I6: 2024
B8: Revenue Growth | H8: 0.10350333 | I8: 0.086390331
B9: COGS (% of revenue) | G9: 0.71735387 | H9: 0.72797685 | I9: 0.72829834
B10: SG&A (% of revenue) | G10: 0.16261232 | H10: 0.15453797 | I10: 0.1496135
C12: Revenue | G12: 3194.1 | H12: 3524.7 | I12: 3829.2
C14: Cost of Sales | G14: 2291.3 | H14: 2565.9 | I14: 2788.8
C15: SG&A | G15: 519.4 | H15: 544.7 | I15: 572.9
C16: Total Costs | G16: =SUM(G14:G15) -> 2810.7 | H16: =SUM(H14:H15) -> 3110.6 | I16: =SUM(I14:I15) -> 3361.7
C18: Cost Adjustments - Gain / (Loss) | G18: -7 | H18: -4.2 | I18: 2
C19: EBITDA | G19: =G12-G16-G18 -> 390.4 | H19: =H12-H16-H18 -> 418.3 | I19: =I12-I16-I18 -> 465.5
C21: Depreciation & Amortization | G21: 95.1 | H21: 113.2 | I21: 126.2
C22: EBIT | G22: =G19-G21 -> 295.3 | H22: =H19-H21 -> 305.1 | I22: =I19-I21 -> 339.3
C24: Cost Adjustments - Gain / (Loss) | G24: 59.9 | H24: 57 | I24: 51.6
C25: Net Interest Expense | G25: 62 | H25: 56.6 | I25: 59.1
C26: EBT | G26: =G22-G24-G25 -> 173.4 | H26: =H22-H24-H25 -> 191.5 | I26: =I22-I24-I25 -> 228.6
C28: Current Taxes | G28: 47.806 | H28: 49.61 | I28: 59.444
C29: Deferred Income Taxes | G29: 16.9 | H29: 31.7 | I29: 24
C30: Total Income Taxes | G30: =SUM(G28:G29) -> 64.706 | H30: =SUM(H28:H29) -> 81.31 | I30: =SUM(I28:I29) -> 83.444
C32: Net Income | G32: =G26-G30 -> 108.694 | H32: =H26-H30 -> 110.19 | I32: =I26-I30 -> 145.156
C34: Preferred Dividend | G34: 0.544 | H34: 0.544 | I34: 0.544
C35: Net Income to Common | G35: =G32-G34 -> 108.15 | H35: =H32-H34 -> 109.646 | I35: =I32-I34 -> 144.612
B37: FED Manufacruring
B38: Cash Flow Statement
B40: ($ Millions)
G41: 2022 | H41: 2023 | I41: 2024
B43: Operating Activities
C44: Net Income | G44: 108.694 | H44: 110.19 | I44: 145.156
C45: Depreciation | G45: 95.1 | H45: 113.2 | I45: 126.2
C46: Deferred Income Taxes | G46: 16.9 | H46: 31.7 | I46: 24
C47: Changes in Working Capital | G47: -119 | H47: -4.5 | I47: -83.8
C48: Other | G48: 161.9 | H48: 164.2 | I48: 242.1
C49: Operating Cash Flow | G49: =SUM(G44:G48) -> 263.594 | H49: =SUM(H44:H48) -> 414.79 | I49: =SUM(I44:I48) -> 453.656
B51: Investing Activities
C52: CAPEX | G52: -134.4 | H52: -158.7 | I52: -194.1
C53: Asset Disposal | G53: 2 | H53: 3.4 | I53: 10.5
C54: Other | G54: -14.9 | H54: -11.3 | I54: -15.4
C55: Investing Cash Flow | G55: =SUM(G52:G54) -> -147.3 | H55: =SUM(H52:H54) -> -166.6 | I55: =SUM(I52:I54) -> -199
...

Sheet Summary
B2: =Hist!B1 -> FED Manufacturing
B3: Summary
J4: ="BS Check "&BS_Check -> BS Check OK | L4: =LiveScenario -> Scenario: Base Case
I6: Actual | J6: Actual | K6: Actual | L6: Forecast | M6: Forecast | N6: Forecast | O6: Forecast | P6: Forecast
D7: Description | E7: Units | F7: Trend | I7: =Hist!G6 -> 2022 | J7: =Hist!H6 -> 2023 | K7: =Hist!I6 -> 2024 | L7: =K7+1 -> 2025 | M7: =L7+1 -> 2026 | N7: =M7+1 -> 2027 | O7: =N7+1 -> 2028 | P7: =O7+1 -> 2029
B9: Model Summary
C10: Summary Based on Scenario: Base Case
C12: Revenue
D13: Gross Revenue | E13: $'m | I13: 3194.1 | J13: 3524.7 | K13: 3829.2 | L13: 3981.41 | M13: 4094.4926 | N13: 4274.2186 | O13: 4395.8286 | P13: 4588.1924
D14: Growth Rate | E14: %age | J14: 0.10350333 | K14: 0.086390331 | L14: 0.039749817 | M14: 0.028402651 | N14: 0.043894584 | O14: 0.028451967 | P14: 0.04376053
C16: EBITDA
D17: EBITDA | E17: $'m | I17: 390.4 | J17: 418.3 | K17: 465.5 | L17: 467.14462 | M17: 492.37058 | N17: 552.15834 | O17: 580.71676 | P17: 646.30457
D18: Growth Rate | E18: %age | J18: 0.071465164 | K18: 0.11283768 | L18: 0.0035330162 | M18: 0.054000334 | N18: 0.12142837 | O18: 0.051721432 | P18: 0.11294286
D19: EBITDA Margin | E19: %age | I19: 0.12222535 | J19: 0.11867677 | K19: 0.12156586 | L19: 0.11733145 | M19: 0.12025192 | N19: 0.12918346 | O19: 0.13210633 | P19: 0.14086257
C21: Net Profit
D22: Net Profit | E22: $'m | I22: 108.694 | J22: 110.19 | K22: 145.156 | L22: 174.79582 | M22: 201.06675 | N22: 239.07092 | O22: 256.75853 | P22: 302.1845
D23: Growth Rate | E23: %age | J23: 0.013763409 | K23: 0.31732462 | L23: 0.2041929 | M23: 0.15029491 | N23: 0.18901272 | O23: 0.07398478 | P23: 0.17692098
D24: Net Profit Margin | E24: %age | I24: 0.034029617 | J24: 0.031262235 | K24: 0.037907657 | L24: 0.043902995 | M24: 0.049106633 | N24: 0.055933245 | O24: 0.058409587 | P24: 0.065861341
C26: Dupont Analysis
D27: ROE | E27: %age | I27: 14.589799 | J27: 1.8124548 | K27: 0.87124268 | L27: 0.4995769 | M27: 0.36769774 | N27: 0.30668501 | O27: 0.25266751 | P27: 0.23688393
D28: Net Profit Margin | E28: %age | I28: 0.034029617 | J28: 0.031262235 | K28: 0.037907657 | L28: 0.043902995 | M28: 0.049106633 | N28: 0.055933245 | O28: 0.058409587 | P28: 0.065861341
D29: Asset Turnover | E29: multiple | I29: 1.6087537 | J29: 1.1679329 | K29: 1.2776316 | L29: 1.5326648 | M29: 1.5513802 | N29: 1.4918385 | O29: 1.4311922 | P29: 1.3903555
D30: Financial Leverage | E30: ratio | I30: 266.50336 | J30: 49.639713 | K30: 17.98898 | L30: 7.4243939 | M30: 4.8265027 | N30: 3.6753671 | O30: 3.022507 | P30: 2.5868973
C32: Summary Based on Scenario: Best Case
C34: Revenue
D35: Gross Revenue | E35: $'m | I35: 3194.1 | J35: 3524.7 | K35: 3829.2 | L35: 4052.605 | M35: 4242.3912 | N35: 4508.4235 | O35: 4720.2184 | P35: 5016.2186
D36: Growth Rate | E36: %age | J36: 0.10350333 | K36: 0.086390331 | L36: 0.058342474 | M36: 0.046830656 | N36: 0.062708123 | O36: 0.04697759 | P36: 0.062708996
C38: EBITDA
D39: EBITDA | E39: $'m | I39: 390.4 | J39: 418.3 | K39: 465.5 | L39: 566.43001 | M39: 703.92354 | N39: 887.85985 | O39: 1045.3463 | P39: 1256.3272
D40: Growth Rate | E40: %age | J40: 0.071465164 | K40: 0.11283768 | L40: 0.21682065 | M40: 0.24273701 | N40: 0.26130155 | O40: 0.17737756 | P40: 0.20182874
D41: EBITDA Margin | E41: %age | I41: 0.12222535 | J41: 0.11867677 | K41: 0.12156586 | L41: 0.13976936 | M41: 0.16592613 | N41: 0.19693355 | O41: 0.22146142 | P41: 0.25045304
C43: Net Profit
D44: Net Profit | E44: $'m | I44: 108.694 | J44: 110.19 | K44: 145.156 | L44: 239.33133 | M44: 339.16872 | N44: 460.19986 | O44: 568.92757 | P44: 716.26875
D45: Growth Rate | E45: %age | J45: 0.013763409 | K45: 0.31732462 | L45: 0.64878703 | M45: 0.41715135 | N45: 0.35684643 | O45: 0.23626194 | P45: 0.25898054
D46: Net Profit Margin | E46: %age | I46: 0.034029617 | J46: 0.031262235 | K46: 0.037907657 | L46: 0.05905617 | M46: 0.079947536 | N46: 0.10207556 | O46: 0.12052993 | P46: 0.14279058
C48: Dupont Analysis
D49: ROE | E49: %age | I49: 14.589799 | J49: 1.8124548 | K49: 0.87124268 | L49: 0.60779185 | M49: 0.49541189 | N49: 0.4310224 | O49: 0.37512679 | P49: 0.3480956
D50: Net Profit Margin | E50: %age | I50: 0.034029617 | J50: 0.031262235 | K50: 0.037907657 | L50: 0.05905617 | M50: 0.079947536 | N50: 0.10207556 | O50: 0.12052993 | P50: 0.14279058
D51: Asset Turnover | E51: multiple | I51: 1.6087537 | J51: 1.1679329 | K51: 1.2776316 | L51: 1.5395495 | M51: 1.5584004 | N51: 1.5470459 | O51: 1.4936927 | P51: 1.4262791
D52: Financial Leverage | E52: ratio | I52: 266.50336 | J52: 49.639713 | K52: 17.98898 | L52: 6.6849156 | M52: 3.9763288 | N52: 2.7294482 | O52: 2.0836364 | P52: 1.7092062
...

Sheet Inp
B2: =Hist!B1 -> FED Manufacturing
B3: Inputs & Assumptions
J4: ="BS Check "&BS_Check -> BS Check OK | L4: =LiveScenario -> Scenario: Base Case
I6: Actual | J6: Actual | K6: Actual | L6: Forecast | M6: Forecast | N6: Forecast | O6: Forecast | P6: Forecast
D7: Description | E7: Units | F7: Input | I7: =Hist!G6 -> 2022 | J7: =Hist!H6 -> 2023 | K7: =Hist!I6 -> 2024 | L7: =K7+1 -> 2025 | M7: =L7+1 -> 2026 | N7: =M7+1 -> 2027 | O7: =N7+1 -> 2028 | P7: =O7+1 -> 2029
B9: Inputs & Assumptions
C10: General Model Assumptions
D11: Days in a period | E11: days | I11: =DATE(I7,12,31)-DATE(I7,1,1)+1 -> 365 | J11: =DATE(J7,12,31)-DATE(J7,1,1)+1 -> 365 | K11: =DATE(K7,12,31)-DATE(K7,1,1)+1 -> 366 | L11: =DATE(L7,12,31)-DATE(L7,1,1)+1 -> 365 | M11: =DATE(M7,12,31)-DATE(M7,1,1)+1 -> 365 | N11: =DATE(N7,12,31)-DATE(N7,1,1)+1 -> 365 | O11: =DATE(O7,12,31)-DATE(O7,1,1)+1 -> 366 | P11: =DATE(P7,12,31)-DATE(P7,1,1)+1 -> 365
D12: Million constant | E12: divisor | F12: 1000000
D13: Thousand constant | E13: divisor | F13: 1000
C16: Model Style Guide
D17: Normal style | E17: number | F17: 1234.5
D18: Input cells | E18: number
D19: Percent | E19: %age | F19: 0.05
D20: Multiples | E20: times | F20: 5
D21: Linked cell | E21: number
D22: Units | E22: Text | F22: Text
D23: Headings 1 | E23: Text | F23: Text
D24: Headings 2 | E24: Text | F24: Text
D25: Headings 3 | E25: Text | F25: Text
D26: Currency | E26: currency | F26: $'m
D27: Subtotal | E27: number | F27: 1234.5
D28: Grand totals | E28: number | F28: 12345
C32: Revenue Assumptions
D33: Average Sales Price | E33: $ | K33: 11600
D34: Total Revenue | E34: =currency -> $'m | K34: =Hist!I12 -> 3829.2 | L34: ="<< "&_xlfn.FORMULATEXT(K34) -> << =Hist!I12
D35: Auxillary Sales | E35: =currency -> $'m | K35: 623.5
D36: Net Revenue | E36: =currency -> $'m | K36: =K34-K35 -> 3205.7 | L36: ="<< "&_xlfn.FORMULATEXT(K36) -> << =K34-K35
D37: Volume | E37: units | K37: =K36*million/K33 -> 276353.45 | L37: ="<< "&_xlfn.FORMULATEXT(K37) -> << =K36*million/K33
D38: Volume Constraint | E38: units | L38: 280000 | M38: 280000 | N38: 285000 | O38: 285000 | P38: 290000
D40: Price Growth | E40: %age | K40: =_xlfn.FORMULATEXT(L40)&">>" -> =Scenarios!L18>> | L40: =Scenarios!L18 -> 0.03 | M40: =Scenarios!M18 -> 0.03 | N40: =Scenarios!N18 -> 0.03 | O40: =Scenarios!O18 -> 0.03 | P40: =Scenarios!P18 -> 0.03
D41: Volume Growth | E41: %age | K41: =_xlfn.FORMULATEXT(L41)&">>" -> =Scenarios!L24>> | L41: =Scenarios!L24 -> 0.04 | M41: =Scenarios!M24 -> 0.04 | N41: =Scenarios!N24 -> 0.04 | O41: =Scenarios!O24 -> 0.04 | P41: =Scenarios!P24 -> 0.04
D42: Auxiliary Sales Growth | E42: %age | K42: =_xlfn.FORMULATEXT(L42)&">>" -> =Scenarios!L30>> | L42: =Scenarios!L30 -> 0.02 | M42: =Scenarios!M30 -> 0.02 | N42: =Scenarios!N30 -> 0.02 | O42: =Scenarios!O30 -> 0.02 | P42: =Scenarios!P30 -> 0.02
C45: Operating Cost Assumptions
D46: Fixed Costs | E46: %age | F46: =1-F47 -> 0.45
D47: Variable Costs | E47: %age | F47: 0.55
D48: Cost Inflation | E48: %age | K48: =_xlfn.FORMULATEXT(L48)&">>" -> =Scenarios!L36>> | L48: =Scenarios!L36 -> 0.025 | M48: =Scenarios!M36 -> 0.025 | N48: =Scenarios!N36 -> 0.025 | O48: =Scenarios!O36 -> 0.025 | P48: =Scenarios!P36 -> 0.025
D49: SG&A | L49: 635
C52: Capex & Depreciation Assumptions
C53: Capex (Tangible Assets
...

Sheet Scenarios
B2: =Hist!B1 -> FED Manufacturing
B3: Scenarios
J4: ="BS Check "&BS_Check -> BS Check OK | L4: =LiveScenario -> Scenario: Base Case
I6: Actual | J6: Actual | K6: Actual | L6: Forecast | M6: Forecast | N6: Forecast | O6: Forecast | P6: Forecast
D7: Description | E7: Units | F7: Input | I7: =Hist!G6 -> 2022 | J7: =Hist!H6 -> 2023 | K7: =Hist!I6 -> 2024 | L7: =K7+1 -> 2025 | M7: =L7+1 -> 2026 | N7: =M7+1 -> 2027 | O7: =N7+1 -> 2028 | P7: =O7+1 -> 2029
B9: Scenario Analysis
C10: Scenarios
D11: {="Scenario: "&INDEX(L_Scenarios,S_Scenarios)} -> Scenario: Base Case
D12: Base Case | E12: 1
D13: Best Case
D14: Worst Case
C17: Price Growth Scenario
D18: Used in model | L18: {=INDEX(L19:L21,S_Scenarios)} -> 0.03 | M18: {=INDEX(M19:M21,S_Scenarios)} -> 0.03 | N18: {=INDEX(N19:N21,S_Scenarios)} -> 0.03 | O18: {=INDEX(O19:O21,S_Scenarios)} -> 0.03 | P18: {=INDEX(P19:P21,S_Scenarios)} -> 0.03
D19: Base Case | E19: %age | L19: 0.03 | M19: 0.03 | N19: 0.03 | O19: 0.03 | P19: 0.03
D20: Best Case | E20: %age | L20: 0.05 | M20: 0.05 | N20: 0.05 | O20: 0.05 | P20: 0.05
D21: Worst Case | E21: %age | L21: 0.02 | M21: 0.02 | N21: 0.02 | O21: 0.02 | P21: 0.02
C23: Volume Growth Scenario
D24: Used in model | L24: {=INDEX(L25:L27,S_Scenarios)} -> 0.04 | M24: {=INDEX(M25:M27,S_Scenarios)} -> 0.04 | N24: {=INDEX(N25:N27,S_Scenarios)} -> 0.04 | O24: {=INDEX(O25:O27,S_Scenarios)} -> 0.04 | P24: {=INDEX(P25:P27,S_Scenarios)} -> 0.04
D25: Base Case | E25: %age | L25: 0.04 | M25: 0.04 | N25: 0.04 | O25: 0.04 | P25: 0.04
D26: Best Case | E26: %age | L26: 0.06 | M26: 0.06 | N26: 0.06 | O26: 0.06 | P26: 0.06
D27: Worst Case | E27: %age | L27: 0.02 | M27: 0.02 | N27: 0.02 | O27: 0.02 | P27: 0.02
C29: Auxiliary Revenue Growth
D30: Used in model | L30: {=INDEX(L31:L33,S_Scenarios)} -> 0.02 | M30: {=INDEX(M31:M33,S_Scenarios)} -> 0.02 | N30: {=INDEX(N31:N33,S_Scenarios)} -> 0.02 | O30: {=INDEX(O31:O33,S_Scenarios)} -> 0.02 | P30: {=INDEX(P31:P33,S_Scenarios)} -> 0.02
D31: Base Case | E31: %age | L31: 0.02 | M31: 0.02 | N31: 0.02 | O31: 0.02 | P31: 0.02
D32: Best Case | E32: %age | L32: 0.03 | M32: 0.03 | N32: 0.03 | O32: 0.03 | P32: 0.03
D33: Worst Case | E33: %age | L33: 0.01 | M33: 0.01 | N33: 0.01 | O33: 0.01 | P33: 0.01
C35: Cost Inflation Scenario
D36: Used in model | L36: {=INDEX(L37:L39,S_Scenarios)} -> 0.025 | M36: {=INDEX(M37:M39,S_Scenarios)} -> 0.025 | N36: {=INDEX(N37:N39,S_Scenarios)} -> 0.025 | O36: {=INDEX(O37:O39,S_Scenarios)} -> 0.025 | P36: {=INDEX(P37:P39,S_Scenarios)} -> 0.025
D37: Base Case | E37: %age | L37: 0.025 | M37: 0.025 | N37: 0.025 | O37: 0.025 | P37: 0.025
D38: Best Case | E38: %age | L38: 0.015 | M38: 0.015 | N38: 0.015 | O38: 0.015 | P38: 0.015
D39: Worst Case | E39: %age | L39: 0.035 | M39: 0.035 | N39: 0.035 | O39: 0.035 | P39: 0.035

Sheet Model
B2: =Hist!B1 -> FED Manufacturing
B3: Model & Schedules
J4: ="BS Check "&BS_Check -> BS Check OK | L4: =LiveScenario -> Scenario: Base Case
I6: Actual | J6: Actual | K6: Actual | L6: Forecast | M6: Forecast | N6: Forecast | O6: Forecast | P6: Forecast
D7: Description | E7: Units | F7: Input | I7: =Hist!G6 -> 2022 | J7: =Hist!H6 -> 2023 | K7: =Hist!I6 -> 2024 | L7: =K7+1 -> 2025 | M7: =L7+1 -> 2026 | N7: =M7+1 -> 2027 | O7: =N7+1 -> 2028 | P7: =O7+1 -> 2029
B9: Financial Statements
C10: Income Statement
D11: =Hist!C12 -> Revenue | E11: =currency -> $'m | I11: =Hist!G12 -> 3194.1 | J11: =Hist!H12 -> 3524.7 | K11: =Hist!I12 -> 3829.2 | L11: =L130 -> 3981.41 | M11: =M130 -> 4094.4926 | N11: =N130 -> 4274.2186 | O11: =O130 -> 4395.8286 | P11: =P130 -> 4588.1924 | Q11: =_xlfn.FORMULATEXT(L11) -> =L130
D12: =Hist!C14 -> Cost of Sales | E12: =currency -> $'m | I12: =Hist!G14 -> 2291.3 | J12: =Hist!H14 -> 2565.9 | K12: =Hist!I14 -> 2788.8 | L12: =L143 -> 2879.2654 | M12: =M143 -> 2951.247 | N12: =N143 -> 3054.9134 | O12: =O143 -> 3131.2863 | P12: =P143 -> 3240.9666 | Q12: =_xlfn.FORMULATEXT(L12) -> =L143
D13: =Hist!C15 -> SG&A | E13: =currency -> $'m | I13: =Hist!G15 -> 519.4 | J13: =Hist!H15 -> 544.7 | K13: =Hist!I15 -> 572.9 | L13: =L151 -> 635 | M13: =M151 -> 650.875 | N13: =N151 -> 667.14687 | O13: =O151 -> 683.82555 | P13: =P151 -> 700.92119 | Q13: =_xlfn.FORMULATEXT(L13) -> =L151
D14: =Hist!C16 -> Total Costs | E14: =currency -> $'m | I14: =I12+I13 -> 2810.7 | J14: =J12+J13 -> 3110.6 | K14: =K12+K13 -> 3361.7 | L14: =L12+L13 -> 3514.2654 | M14: =M12+M13 -> 3602.122 | N14: =N12+N13 -> 3722.0603 | O14: =O12+O13 -> 3815.1118 | P14: =P12+P13 -> 3941.8878 | Q14: =_xlfn.FORMULATEXT(L14) -> =L12+L13
D15: =Hist!C18 -> Cost Adjustments - Gain / (Loss) | E15: =currency -> $'m | I15: =Hist!G18 -> -7 | J15: =Hist!H18 -> -4.2 | K15: =Hist!I18 -> 2 | L15: =Inp!L125 -> 0 | M15: =Inp!M125 -> 0 | N15: =Inp!N125 -> 0 | O15: =Inp!O125 -> 0 | P15: =Inp!P125 -> 0 | Q15: =_xlfn.FORMULATEXT(L15) -> =Inp!L125
D16: =Hist!C19 -> EBITDA | E16: =currency -> $'m | I16: =I11-I14-I15 -> 390.4 | J16: =J11-J14-J15 -> 418.3 | K16: =K11-K14-K15 -> 465.5 | L16: =L11-L14-L15 -> 467.14462 | M16: =M11-M14-M15 -> 492.37058 | N16: =N11-N14-N15 -> 552.15834 | O16: =O11-O14-O15 -> 580.71676 | P16: =P11-P14-P15 -> 646.30457 | Q16: =_xlfn.FORMULATEXT(L16) -> =L11-L14-L15
D17: =Hist!C21 -> Depreciation & Amortization | E17: =currency -> $'m | I17: =Hist!G21 -> 95.1 | J17: =Hist!H21 -> 113.2 | K17: =Hist!I21 -> 126.2 | L17: =L173+L196 -> 118.34977 | M17: =M173+M196 -> 127.04926 | N17: =N173+N196 -> 134.98573 | O17: =O173+O196 -> 143.03134 | P17: =P173+P196 -> 151.08431 | Q17: =_xlfn.FORMULATEXT(L17) -> =L173+L196
D18: =Hist!C22 -> EBIT | E18: =currency -> $'m | I18: =I16-I17 -> 295.3 | J18: =J16-J17 -> 305.1 | K18: =K16-K17 -> 339.3 | L18: =L16-L17 -> 348.79485 | M18: =M16-M17 -> 365.32132 | N18: =N16-N17 -> 417.17261 | O18: =O16-O17 -> 437.68542 | P18: =P16-P17 -> 495.22026 | Q18: =_xlfn.FORMULATEXT(L18) -> =L16-L17
D19: =Hist!C24 -> Cost Adjustments - Gain / (Loss) | E19: =currency -> $'m | I19: =Hist!G24 -> 59.9 | J19: =Hist!H24 -> 57 | K19: =Hist!I24 -> 51.6 | L19: =Inp!L126 -> 0 | M19: =Inp!M126 -> 0 | N19: =Inp!N126 -> 0 | O19: =Inp!O126 -> 0 | P19: =Inp!P126 -> 0 | Q19: =_xlfn.FORMULATEXT(L19) -> =Inp!L126
D20: =Hist!C25 -> Net Interest Expense | E20: =currency -> $'m | I20: =Hist!G25 -> 62 | J20: =Hist!H25 -> 56.6 | K20: =Hist!I25 -> 59.1 | L20: =L326 -> 76.3421 | M20: =M326 -> 52.206041 | N20: =N326 -> 54.571556 | O20: =O326 -> 56.580929 | P20: =P326 -> 57.606353 | Q20: =_xlfn.FORMULATEXT(L20) -> =L326
D21: =Hist!C26 -> EBT | E21: =currency -> $'m | I21: =I18-I19-I20 -> 173.4 | J21: =J18-J19-J20 -> 191.5 | K21: =K18-K19-K20 -> 228.6 | L21: =L18-L19-L20 -> 272.45275 | M21: =M18-M19-M20 -> 313.11528 | N21: =N18-N19-N20 -> 362.60105 | O21: =O18-O19-O20 -> 381.1045 | P21: =P18-P19-P20 -> 437.61391 | Q21: =_xlfn.FORMULATEXT(L21) -> =L18-L19-L20
D22: =Hist!C28 -> Current Taxes | E22: =currency -> $'m | I22: =Hist!G28 -> 47.806 | J22: =Hist!H28 -> 49.61 | K22: =Hist!I28 -> 59.444 | L22: =L207 -> 103.75846 | M22: =M207 -> 117.99035 | N22: =N207 -> 135.31037 | O22: =O207 -> 141.78657 | P22: =P207 -> 161.56487 | Q22: =_xlfn.FORMULATEXT(L22) -> =L207
D23: =Hist!C29 -> Deferred Income Taxes | E23: =currency -> $'m | I23: =Hist!G29 -> 16.9 | J23: =Hist!H29 -> 31.7 | K23: =Hist!I29 -> 24 | L23: =-L208 -> -8.4 | M23: =-M208 -> -8.4 | N23: =-N208 -> -8.4 | O23: =-O208 -> -8.4 | P23: =-P208 -> -8.4 | Q23: =_xlfn.FORMULATEXT(L23) -> =-L208
D24: =Hist!C30 -> Total Income Taxes | E24: =currency -> $'m | I24: =I22+I23 -> 64.706 | J24: =J22+J23 -> 81.31 | K24: =K22+K23 -> 83.444 | L24: =L22+L23 -> 95.358461 | M24: =M22+M23 -> 109.59035 | N24: =N22+N23 -> 126.91037 | O24: =O22+O23 -> 133.38657 | P24: =P22+P23 -> 153.16487 | Q24: =_xlfn.FORMULATEXT(L24) -> =L22+L23
D25: =Hist!C32 -> Net Income | E25: =currency -> $'m | I25: =I21-I24 -> 108.694 | J25: =J21-J24 -> 110.19 | K25: =K21-K24 -> 145.156 | L25: =L21-L24 -> 177.09429 | M25: =M21-M24 -> 203.52493 | N25: =N21-N24 -> 235.69068 | O25: =O21-O24 -> 247.71792 | P25: =P21-P24 -> 284.44904 | Q25: =_xlfn.FORMULATEXT(L25) -> =L21-L24
D26: =Hist!C34 -> Preferred Dividend | E26: =currency -> $'m | I26: =Hist!G34 -> 0.544 | J26: =Hist!H34 -> 0.544 | K26: =Hist!I34 -> 0.544 | L26: =L338 -> 2.888 | M26: =M338 -> 7.3055 | N26: =N338 -> 11.5805 | O26: =O338 -> 15.8555 | P26: =P338 -> 20.1305 | Q26: =_xlfn.FORMULATEXT(L26) -> =L338
D27: =Hist!C35 -> Net Income to Common | E27: =currency -> $'m | I27: =Hist!G35 -> 108.15 | J27: =Hist!H35 -> 109.646 | K27: =Hist!I35 -> 144.612 | L27: =L25-L26 -> 174.20629 | M27: =M25-M26 -> 196.21943 | N27: =N25-N26 -> 224.11018 | O27: =O25-O26 -> 231.86242 | P27: =P25-P26 -> 264.31854 | Q27: =_xlfn.FORMULATEXT(L27) -> =L25-L26
D29: EBITDA Margin | E29: %age | I29: =I16/I11 -> 0.12222535 | J29: =J16/J11 -> 0.11867677 | K29: =K16/K11 -> 0.12156586 | L29: =L16/L11 -> 0.11733145 | M29: =M16/M11 -> 0.12025192 | N29: =N16/N11 -> 0.12918346 | O29: =O16/O11 -> 0.13210633 | P29: =P16/P11 -> 0.14086257 | Q29: =_xlfn.FORMULATEXT(L29) -> =L16/L11
C30: Dupont Analysis
D31: ROE | E31: %age | I31: =I25/I104 -> 14.589799 | J31: =J25/J104 -> 1.8124548 | K31: =K25/K104 -> 0.87124268 | L31: =L25/L104 -> 0.72857836 | M31: =M25/M104 -> 0.54785009 | N31: =N25/N104 -> 0.43899053 | O31: =O25/O104 -> 0.35010221 | P31: =P25/P104 -> 0.31595076 | Q31: =_xlfn.FORMULATEXT(L31) -> =L25/L104
D32: Net Profit Margin | E32: %age | I32: =I25/I11 -> 0.034029617 | J32: =J25/J11 -> 0.031262235 | K32: =K25/K11 -> 0.037907657 | L32: =L25/L11 -> 0.044480293 | M32: =M25/M11 -> 0.049706997 | N32: =N25/N11 -> 0.055142402 | O32: =O25/O11 -> 0.056352953 | P32: =P25/P11 -> 0.061995884 | Q32: =_xlfn.FORMULATEXT(L32) -> =L25/L11
D33: Asset Turnover | E33: multiple | I33: =I11/I85 -> 1.6087537 | J33: =J11/J85 -> 1.1679329 | K33: =K11/K85 -> 1.2776316 | L33: =L11/L85 -> 1.5983919 | M33: =M11/M85 -> 1.5450557 | N33: =N11/N85 -> 1.482563 | O33: =O11/O85 -> 1.4214336 | P33: =P11/P85 -> 1.3839487 | Q33: =_xlfn.FORMULATEXT(L33) -> =L11/L85
D34: Financial Leverage | E34: ratio | I34: =I85/I104 -> 266.50336 | J34: =J85/J104 -> 49.639713 | K34: =K85/K104 -> 17.98898 | L34: =L85/L104 -> 10.247676 | M34: =M85/M104 -> 7.1334573 | N34: =N85/N104 -> 5.3697778 | O34: =O85/O104 -> 4.3707061 | P34: =P85/P104 -> 3.6824475 | Q34: =_xlfn.FORMULATEXT(L34) -> =L85/L104
C39: Cashflow Statement
C40: =Hist!B43 -> Operating Activities
D41: =Hist!C44 -> Net Income | E41: $'m | I41: =Hist!G44 -> 108.694 | J41: =Hist!H44 -> 110.19 | K41: =Hist!I44 -> 145.156 | L41: =L25 -> 177.09429 | M41: =M25 -> 203.52493 | N41: =N25 -> 235.69068 | O41: =O25 -> 247.71792 | P41: =P25 -> 284.44904 | Q41: =_xlfn.FORMULATEXT(L41) -> =L25
D42: =Hist!C45 -> Depreciation | E42: $'m | I42: =Hist!G45 -> 95.1 | J42: =Hist!H45 -> 113.2 | K42: =Hist!I45 -> 126.2 | L42: =L17 -> 118.34977 | M42: =M17 -> 127.04926 | N42: =N17 -> 134.98573 | O42: =O17 -> 143.03134 | P42: =P17 -> 151.08431 | Q42: =_xlfn.FORMULATEXT(L42) -> =L17
D43: =Hist!C46 -> Deferred Income Taxes | E43: $'m | I43: =Hist!G46 -> 16.9 | J43: =Hist!H46 -> 31.7 | K43: =Hist!I46 -> 24 | L43: =L23 -> -8.4 | M43: =M23 -> -8.4 | N43: =N23 -> -8.4 | O43: =O23 -> -8.4 | P43: =P23 -> -8.4 | Q43: =_xlfn.FORMULATEXT(L43) -> =L23
D44: =Hist!C47 -> Changes in Working Capital | E44: $'m | I44: =Hist!G47 -> -119 | J44: =Hist!H47 -> -4.5 | K44: =Hist!I47 -> -83.8 | L44: =L234 -> -7.3676731 | M44: =M234 -> -4.8558723 | N44: =N234 -> -8.3556147 | O44: =O234 -> -4.8220074 | P44: =P234 -> -9.4806003 | Q44: =_xlfn.FORMULATEXT(L44) -> =L234
D45: =Hist!C48 -> Other | E45: $'m | I45: =Hist!G48 -> 161.9 | J45: =Hist!H48 -> 164.2 | K45: =Hist!I48 -> 242.1 | L45: =Inp!L131 -> 0 | M45: =Inp!M131 -> 0 | N45: =Inp!N131 -> 0 | O45: =Inp!O131 -> 0 | P45: =Inp!P131 -> 0 | Q45: =_xlfn.FORMULATEXT(L45) -> =Inp!L131
D46: =Hist!C49 -> Operating Cash Flow | E46: $'m | I46: =SUM(I41:I45) -> 263.594 | J46: =SUM(J41:J45) -> 414.79 | K46: =SUM(K41:K45) -> 453.656 | L46: =SUM(L41:L45) -> 279.67638 | M46: =SUM(M41:M45) -> 317.31832 | N46: =SUM(N41:N45) -> 353.9208 | O46: =SUM(O41:O45) -> 377.52725 | P46: =SUM(P41:P45) -> 417.65275 | Q46: =_xlfn.FORMULATEXT(L46) -> =SUM(L41:L45)
C48: =Hist!B51 -> Investing Activities | E48: $'m
D49: =Hist!C52 -> CAPEX | E49: $'m | I49: =Hist!G52 -> -134.4 | J49: =Hist!H52 -> -158.7 | K49: =Hist!I52 -> -194.1 | L49: =-SUM(L172,L195) -> -297 | M49: =-SUM(M172,M195) -> -332 | N49: =-SUM(N172,N195) -> -317 | O49: =-SUM(O172,O195) -> -317 | P49: =-SUM(P172,P195) -> -317 | Q49: =_xlfn.FORMULATEXT(L49) -> =-SUM(L172,L195)
...

Sheet Template
B2: =Hist!B1 -> FED Manufacturing
B3: Template
J4: ="BS Check "&BS_Check -> BS Check OK | L4: =LiveScenario -> Scenario: Base Case
I6: Actual | J6: Actual | K6: Actual | L6: Forecast | M6: Forecast | N6: Forecast | O6: Forecast | P6: Forecast
D7: Description | E7: Units | F7: Input | I7: =Hist!G6 -> 2022 | J7: =Hist!H6 -> 2023 | K7: =Hist!I6 -> 2024 | L7: =K7+1 -> 2025 | M7: =L7+1 -> 2026 | N7: =M7+1 -> 2027 | O7: =N7+1 -> 2028 | P7: =O7+1 -> 2029
